Workbook

Sheet Cover
A1: COMPANY LOGO | C1: PROJECT TITLE
A7: COMPANY Doc No. : XXXXXXXXXXXXXXX | C7: PROCESS DATA SHEET DESCRIPTION TAG NO | G7: Rev. No. :
G8: Date :
A9: Document Class: X | G9: Page: 1 of 2
A10: PROJECT TITLE COMPANY PROJECT NO. XXXXXX CONTRACT NO. XXXXXXXX PROCESS DATA SHEET DESCRIPTION TAG NO COMPANY DOCUMENT NO.: XXXXXXXXXX
A55: REV NO. | B55: DATE | C55: DESCRIPTION | F55: PREPARED BY | G55: REVIEWED BY | H55: APPROVED BY
A57: RAD-PR-TMP-0001, Rev 0

Sheet Sheet 1
A1: =Cover!A1 -> COMPANY LOGO | J1: =Cover!C1 -> PROJECT TITLE
A7: =Cover!A7 -> COMPANY Doc No. : XXXXXXXXXXXXXXX | J7: =Cover!C7 -> PROCESS DATA SHEET DESCRIPTION TAG NO | AD7: =Cover!G7 -> Rev. No. :
AD8: =Cover!G8 -> Date :
A9: =Cover!A9 -> Document Class: X | AD9: Page: 2 of 2
A10: REV
B11: 1 | C11: APPLICABLE TO: | I11: FEED/DETAILED ENGINEERING DESIGN | T11: APPLICABLE NTL/INTL STANDARD: | AD11: API-610
B12: =B11+1 -> 2 | C12: FOR: | I12: COMPANY NAME | T12: UNIT:
B13: =B12+1 -> 3 | C13: SITE: | I13: OFFSHORE/ONSHORE | T13: SERVICE:
B14: =B13+1 -> 4 | C14: NO. REQUIRED: | T14: TYPE:
B15: =B14+1 -> 5 | C15: MANUFACTURER: | T15: MODEL:
B16: =B15+1 -> 6
B17: =B16+1 -> 7 | C17: LIQUID CHARACTERISTICS
B18: =B17+1 -> 8 | K18: Units | N18: Maximum | Q18: Minimum | T18: Note: | AA18: SERVICE : | AH18: CONTINUOUS
B19: =B18+1 -> 9 | J19: LIQUID TYPE OR NAME : | T19: Max & Min values | AA19: • IF INTERMITTENT NO. OF STARTS :
B20: =B19+1 -> 10 | J20: VAPOR PRESSURE : | T20: refer only to the | AA20: PUMPS OPERATE IN:
B21: =B20+1 -> 11 | C21: DENSITY : | T21: property listed | AA21: CORROSION DUE TO :
B22: =B21+1 -> 12 | J22: SPECIFIC HEAT : | AA22: EROSION DUE TO :
B23: =B22+1 -> 13 | J23: VISCOSITY : | AA23: H2S CONCENTRATION (ppm) :
B24: =B23+1 -> 14
B25: =B24+1 -> 15 | C25: OPERATING CONDITIONS | AA25: CHLORIDE CONCENTRATION (ppm) :
B26: =B25+1 -> 16 | K26: Units | N26: Rated | Q26: Normal | T26: Minimum | AA26: PARTICULATE SIZE (Dia in Micorns)
B27: =B26+1 -> 17 | J27: NPSHa Datum: | AA27: PARTICULATE CONCENTRATION (ppm)
B28: =B27+1 -> 18 | J28: PUMPING TEMPERATURE :
B29: =B28+1 -> 19 | C29: FLOW : | Z29: MATERIAL
B30: =B29+1 -> 20 | AA30: CASING:
B31: =B30+1 -> 21 | J31: DISCHARGE PRESSURE : | AA31: IMPELLER:
B32: =B31+1 -> 22 | J32: SUCTION PRESSURE :
B33: =B32+1 -> 23 | C33: DIFFERENTIAL PRESSURE : | Z33: DESIGN CONDITION
B34: =B33+1 -> 24 | C34: DIFFERENTIAL HEAD : | AA34: DESIGN PRESSURE:
B35: =B34+1 -> 25 | C35: NPSHA : | AA35: DESIGN TEMPERATURE:
B36: =B35+1 -> 26 | C36: HYDRAULIC POWER :
B37: =B36+1 -> 27 | C37: SITE AND UTILITY DATA
B38: =B37+1 -> 28 | C38: COOLING WATER:
B39: =B38+1 -> 29 | L39: INLET | P39: RETURN | U39: DESIGN
B40: =B39+1 -> 30 | D40: TEMPERATURE: | J40: MAX
B41: =B40+1 -> 31 | D41: PRESSURE: | J41: MIN
B42: =B41+1 -> 32 | D42: SOURCE:
B43: =B42+1 -> 33 | D43: COOLING WATER CHLORIDE CONCENTRATION (ppm):
B44: =B43+1 -> 34 | D44: INST AIR PRESSURE: | J44: MAX | P44: MIN
B45: =B44+1 -> 35
...
